Workbook
Name AnalystList: tblAnalysts[Initials]
Name FrmLocationList: tblCoC[From Location]
Name LowerLimList: tblSpecs[Lower Limit]
Name MethodIDList: tblMethods[Method ID]
Name MethodList: tblMethods[Method Name]
Name ProductList: Samples!$C:$C
Name SampleIDList: Samples!$A$2:$A$20
Name UnitList: tblSpecs[Unit]
Name UpperLimList: tblSpecs[Upper Limit]

Sheet Samples
A1: Sample Id | B1: Batch No. | C1: Product Name | D1: Sample Type | E1: Date Received | F1: Time Received | G1: Received From | H1: Logged By | I1: Quantity Received | J1: Unit | K1: Condition on Receipt | L1: Storage Condition | M1: Hazard Level | N1: Manufacture Date | O1: Expiry Date | P1: Sample Status | Q1: Priority | R1: Comments
A2: SMP-2026-0001 | B2: BN-PCM-2601 | C2: Paracetamol | D2: Finished Product | E2: 46138 | F2: 0.4375 | G2: Production | H2: AOB | I2: 30 | J2: Tablets | K2: Contaminated | L2: 15–25°C | M2: None | N2: 46032 | O2: 47238 | P2: Rejected | Q2: Standard | R2: Visible Particulate Matter
A3: SMP-2026-0002 | B3: BN-OZE-2601 | C3: Ozempic | D3: Raw Material | E3: 46099 | F3: 0.45833333 | G3: External | H3: MM | I3: 1.5 | J3: g | K3: Acceptable | L3: 2–8°C | M3: Biohazard | N3: 45978 | O3: 46742 | P3: On Hold | Q3: Urgent | R3: Awaiting CoA
A4: SMP-2026-0003 | B4: BN-PCM-2602 | C4: Paracetamol | D4: Finished Product | E4: 46114 | F4: 0.38541667 | G4: Production | H4: JM | I4: 50 | J4: Tablets | K4: Acceptable | L4: 15–25°C | M4: None | N4: 46109 | O4: 47204 | P4: Released | Q4: Standard
A5: SMP-2026-0004 | B5: BN-PCM-2603 | C5: Paracetamol | D5: Finished Product | E5: 46120 | F5: 0.59722222 | G5: Production | H5: SK | I5: 50 | J5: Tablets | K5: Acceptable | L5: 15–25°C | M5: None | N5: 46114 | O5: 47209 | P5: Approved | Q5: Standard
A6: SMP-2026-0005 | B6: BN-PCM-RM01 | C6: Paracetamol | D6: Raw Material | E6: 46124 | F6: 0.36458333 | G6: Warehouse | H6: JM | I6: 200 | J6: g | K6: Acceptable | L6: 15–25°C | M6: None | N6: 46117 | O6: 46847 | P6: In Testing | Q6: Standard | R6: API receipt
A7: SMP-2026-0006 | B7: BN-PCM-RM02 | C7: Paracetamol | D7: Raw Material | E7: 46126 | F7: 0.39583333 | G7: Warehouse | H7: AOB | I7: 250 | J7: g | K7: Damaged | L7: 15–25°C | M7: None | N7: 46120 | O7: 46850 | P7: On Hold | Q7: Urgent | R7: Container Seal Compromised
A8: SMP-2026-0007 | B8: BN-PCM-ST01 | C8: Paracetamol | D8: Stability | E8: 46132 | F8: 0.54166667 | G8: Stability Chamber | H8: AOB | I8: 20 | J8: Tablets | K8: Acceptable | L8: 25-30°C / 60% RH | M8: None | N8: 45945 | O8: 47040 | P8: In Testing | Q8: Stability | R8: 6 Month timepoint
A9: SMP-2026-0008 | B9: BN-PCM-ST02 | C9: Paracetamol | D9: Stability | E9: 46134 | F9: 0.5625 | G9: Stability Chamber | H9: SK | I9: 20 | J9: Tablets | K9: Acceptable | L9: 40°C / 75% RH | M9: None | N9: 45945 | O9: 47040 | P9: Approved | Q9: Stability | R9: Accelerated 6 month
A10: SMP-2026-0009 | B10: BN-OZE-2602 | C10: Ozempic | D10: Finished Product | E10: 46117 | F10: 0.41666667 | G10: Production | H10: MM | I10: 5 | J10: Vials | K10: Acceptable | L10: 2–8°C | M10: Biohazard | N10: 46113 | O10: 46843 | P10: Released | Q10: Standard
A11: SMP-2026-0010 | B11: BN-OZE-2603 | C11: Ozempic | D11: Finished Product | E11: 46123 | F11: 0.48958333 | G11: Production | H11: AOB | I11: 5 | J11: Vials | K11: Acceptable | L11: 2–8°C | M11: Biohazard | N11: 46118 | O11: 46848 | P11: Approved | Q11: Standard
A12: SMP-2026-0011 | B12: BN-OZE-2604 | C12: Ozempic | D12: Finished Product | E12: 46128 | F12: 0.42708333 | G12: Production | H12: JM | I12: 5 | J12: Vials | K12: Leaking | L12: 2–8°C | M12: Biohazard | N12: 46124 | O12: 46854 | P12: Rejected | Q12: Urgent | R12: Vial Seal Failure
A13: SMP-2026-0012 | B13: BN-OZE-RM01 | C13: Ozempic | D13: Raw Material | E13: 46118 | F13: 0.375 | G13: External | H13: MM | I13: 50 | J13: mg | K13: Acceptable | L13: −20°C | M13: Biohazard | N13: 46113 | O13: 46477 | P13: Released | Q13: Standard | R13: Peptide API
A14: SMP-2026-0013 | B14: BN-OZE-RM02 | C14: Ozempic | D14: Raw Material | E14: 46131 | F14: 0.58333333 | G14: External | H14: AOB | I14: 100 | J14: mg | K14: Acceptable | L14: −20°C | M14: Biohazard | N14: 46126 | O14: 46490 | P14: In Testing | Q14: Standard
A15: SMP-2026-0014 | B15: BN-OZE-ST01 | C15: Ozempic | D15: Stability | E15: 46135 | F15: 0.52083333 | G15: Stability Chamber | H15: SK | I15: 3 | J15: Vials | K15: Acceptable | L15: 2–8°C | M15: Biohazard | N15: 45950 | O15: 46679 | P15: In Testing | Q15: Stability | R15: Long term, 6-month
A16: SMP-2026-0015 | B16: BN-IBU-2601 | C16: Ibuprofen | D16: Finished Product | E16: 46121 | F16: 0.40625 | G16: Production | H16: JM | I16: 40 | J16: Tablets | K16: Acceptable | L16: 15–25°C | M16: None | N16: 46116 | O16: 47211 | P16: Released | Q16: Standard | R16: Gelatin-coated
A17: SMP-2026-0016 | B17: BN-IBU-2602 | C17: Ibuprofen | D17: Finished Product | E17: 46129 | F17: 0.4375 | G17: Production | H17: AOB | I17: 40 | J17: Tablets | K17: Acceptable | L17: 15–25°C | M17: None | N17: 46124 | O17: 47219 | P17: In Testing | Q17: Standard
A18: SMP-2026-0017 | B18: BN-IBU-RMO1 | C18: Ibuprofen | D18: Raw Material | E18: 46125 | F18: 0.35416667 | G18: Warehouse | H18: SK | I18: 300 | J18: g | K18: Acceptable | L18: 15–25°C | M18: None | N18: 46118 | O18: 46848 | P18: Approved | Q18: Standard
A19: SMP-2026-0018 | B19: BN-IBU-ST01 | C19: Ibuprofen | D19: Stability | E19: 46137 | F19: 0.55208333 | G19: Stability Chamber | H19: MM | I19: 25 | J19: Tablets | K19: Acceptable | L19: 30°C / 65% RH | M19: None | N19: 45948 | O19: 47043 | P19: In Testing | Q19: Stability | R19: Intermediate, 6-month

Sheet Test Methods
A1: Method ID | B1: Method Name | C1: SOP Number | D1: Equipment | E1: Unit | F1: Status
A2: TM-001 | B2: pH Test | C2: SOP-PH-04 | D2: pH Meter A | E2: pH units | F2: Active
A3: TM-002 | B3: HPLC Assay | C3: SOP-HPLC-12 | D3: HPLC #3 | E3: % w/w | F3: Active
A4: TM-003 | B4: Appearance | C4: SOP-VIS-01 | D4: Visual | E4: - | F4: Active
A5: TM-004 | B5: Dissolution | C5: SOP-DIS-08 | D5: Dissolution Apparatus II | E5: % released | F5: Active
A6: TM-005 | B6: Water Content (KF) | C6: SOP-KF-05 | D6: Karl Fischer Titrator | E6: % w/w | F6: Active
A7: TM-006 | B7: Microbial Count | C7: SOP-MIC-03 | D7: Plate Reader | E7: CFU/g | F7: Active
A8: TM-007 | B8: LOD (Loss on Drying) | C8: SOP-LOD-02 | D8: Moisture Analyser | E8: % w/w | F8: Retired

Sheet Specifications
A1: Spec Id | B1: Product Name | C1: Method Id | D1: Method Name | E1: Lower Limit | F1: Upper Limit | G1: Unit | H1: SOP Version | I1: Effective Date | J1: Status
A2: SPEC-001 | B2: Paracetamol | C2: TM-001 | D2: pH Test | E2: 5.5 | F2: 6.5 | G2: pH Units | H2: v04 | I2: 45658 | J2: Active
A3: SPEC-002 | B3: Paracetamol | C3: TM-002 | D3: HPLC Assay | E3: 95 | F3: 105 | G3: % w/w | H3: v12 | I3: 45658 | J3: Active
A4: SPEC-003 | B4: Paracetamol | C4: TM-004 | D4: Dissolution | E4: 80 | F4: 100 | G4: % released | H4: v08 | I4: 45658 | J4: Active
A5: SPEC-004 | B5: Paracetamol | C5: TM-007 | D5: LOD (Loss on Drying) | E5: 0 | F5: 0.5 | G5: % w/w | H5: v02 | I5: 45658 | J5: Superseded
A6: SPEC-005 | B6: Ozempic | C6: TM-001 | D6: pH Test | E6: 6.5 | F6: 8 | G6: pH Units | H6: v04 | I6: 45717 | J6: Active
A7: SPEC-006 | B7: Ozempic | C7: TM-002 | D7: HPLC Assay | E7: 98 | F7: 102 | G7: % w/w | H7: v12 | I7: 45717 | J7: Active
A8: SPEC-007 | B8: Ozempic | C8: TM-006 | D8: Microbial Count | E8: 0 | F8: 100 | G8: CFU/g | H8: v03 | I8: 45717 | J8: Active
A9: SPEC-008 | B9: Ibuprofen | C9: TM-002 | D9: HPLC Assay | E9: 90 | F9: 110 | G9: % w/w | H9: v12 | I9: 45689 | J9: Active
A10: SPEC-009 | B10: Ibuprofen | C10: TM-004 | D10: Dissolution | E10: 80 | F10: 100 | G10: % released | H10: v08 | I10: 45689 | J10: Active
A11: SPEC-010 | B11: Ibuprofen | C11: TM-005 | D11: Water Content (KF) | E11: 0 | F11: 5 | G11: % w/w | H11: v05 | I11: 45689 | J11: Active

Sheet Results
A1: Result ID | B1: Sample ID | C1: Product Name | D1: Method ID | E1: Method Name | F1: Test Date | G1: Test Time | H1: Analyst | I1: Measured Value | J1: Unit | K1: Lower Limit | L1: Upper Limit | M1: Pass/Fail | N1: Comments
A2: R-2026-0001 | B2: SMP-2026-0003 | C2: =IF(tblResults[[#This Row],[Sample ID]]="", "", _xlfn.XLOOKUP(tblResults[[#This Row],[Sample ID]], Samples!A:A, Samples!C:C, "")) -> Paracetamol | D2: TM-002 | E2: =IF(tblResults[[#This Row],[Method ID]]="", "", _xlfn.XLOOKUP(tblResults[[#This Row],[Method ID]], 'Test Methods'!A:A, 'Test Methods'!B:B, "")) -> HPLC Assay | F2: 46149 | G2: 0.46927083 | H2: AOB | I2: 95 | J2: {=IF(OR(tblResults[[#This Row],[Product Name]]="", tblResults[[#This Row],[Method Name]]=""), "", _xlfn.XLOOKUP(tblResults[[#This Row],[Product Name]]&tblResults[[#This Row],[Method Name]], Specifications!B:B&Specifications!D:D, Specifications!G:G, "No Spec"))} -> % w/w | K2: {=IF(OR(tblResults[[#This Row],[Product Name]]="", tblResults[[#This Row],[Method Name]]=""), "", _xlfn.XLOOKUP(tblResults[[#This Row],[Product Name]]&tblResults[[#This Row],[Method Name]], Specifications!B:B&Specifications!D:D, Specifications!E:E, "No Spec"))} -> 95 | L2: {=IF(OR(tblResults[[#This Row],[Product Name]]="", tblResults[[#This Row],[Method Name]]=""), "", _xlfn.XLOOKUP(tblResults[[#This Row],[Product Name]]&tblResults[[#This Row],[Method Name]], Specifications!B:B&Specifications!D:D, Specifications!F:F, "No Spec"))} -> 105 | M2: =IF(tblResults[[#This Row],[Measured Value]]="","",IF(NOT(ISNUMBER(tblResults[[#This Row],[Measured Value]])),"Invalid Entry",IF(OR(tblResults[[#This Row],[Lower Limit]]="",tblResults[[#This Row],[Upper Limit]]="",tblResults[[#This Row],[Lower Limit]]="No Spec"),"",IF(AND(tblResults[[#This Row],[Measured Value]]>=tblResults[[#This Row],[Lower Limit]],tblResults[[#This Row],[Measured Value]]<=tblResults[[#This Row],[Upper Limit]]),"Pass","OOS")))) -> Pass
A3: R-2026-0002 | B3: SMP-2026-0005 | C3: =IF(tblResults[[#This Row],[Sample ID]]="", "", _xlfn.XLOOKUP(tblResults[[#This Row],[Sample ID]], Samples!A:A, Samples!C:C, "")) -> Paracetamol | D3: TM-001 | E3: =IF(tblResults[[#This Row],[Method ID]]="", "", _xlfn.XLOOKUP(tblResults[[#This Row],[Method ID]], 'Test Methods'!A:A, 'Test Methods'!B:B, "")) -> pH Test | F3: 46145 | G3: 0.55011574 | H3: JM | I3: 6.2 | J3: {=IF(OR(tblResults[[#This Row],[Product Name]]="", tblResults[[#This Row],[Method Name]]=""), "", _xlfn.XLOOKUP(tblResults[[#This Row],[Product Name]]&tblResults[[#This Row],[Method Name]], Specifications!B:B&Specifications!D:D, Specifications!G:G, "No Spec"))} -> pH Units | K3: {=IF(OR(tblResults[[#This Row],[Product Name]]="", tblResults[[#This Row],[Method Name]]=""), "", _xlfn.XLOOKUP(tblResults[[#This Row],[Product Name]]&tblResults[[#This Row],[Method Name]], Specifications!B:B&Specifications!D:D, Specifications!E:E, "No Spec"))} -> 5.5 | L3: {=IF(OR(tblResults[[#This Row],[Product Name]]="", tblResults[[#This Row],[Method Name]]=""), "", _xlfn.XLOOKUP(tblResults[[#This Row],[Product Name]]&tblResults[[#This Row],[Method Name]], Specifications!B:B&Specifications!D:D, Specifications!F:F, "No Spec"))} -> 6.5 | M3: =IF(tblResults[[#This Row],[Measured Value]]="","",IF(NOT(ISNUMBER(tblResults[[#This Row],[Measured Value]])),"Invalid Entry",IF(OR(tblResults[[#This Row],[Lower Limit]]="",tblResults[[#This Row],[Upper Limit]]="",tblResults[[#This Row],[Lower Limit]]="No Spec"),"",IF(AND(tblResults[[#This Row],[Measured Value]]>=tblResults[[#This Row],[Lower Limit]],tblResults[[#This Row],[Measured Value]]<=tblResults[[#This Row],[Upper Limit]]),"Pass","OOS")))) -> Pass
A4: R-2026-0003 | B4: SMP-2026-0010 | C4: =IF(tblResults[[#This Row],[Sample ID]]="", "", _xlfn.XLOOKUP(tblResults[[#This Row],[Sample ID]], Samples!A:A, Samples!C:C, "")) -> Ozempic | D4: TM-006 | E4: =IF(tblResults[[#This Row],[Method ID]]="", "", _xlfn.XLOOKUP(tblResults[[#This Row],[Method ID]], 'Test Methods'!A:A, 'Test Methods'!B:B, "")) -> Microbial Count | F4: 46141 | G4: 0.66017361 | H4: MM | I4: 10 | J4: {=IF(OR(tblResults[[#This Row],[Product Name]]="", tblResults[[#This Row],[Method Name]]=""), "", _xlfn.XLOOKUP(tblResults[[#This Row],[Product Name]]&tblResults[[#This Row],[Method Name]], Specifications!B:B&Specifications!D:D, Specifications!G:G, "No Spec"))} -> CFU/g | K4: {=IF(OR(tblResults[[#This Row],[Product Name]]="", tblResults[[#This Row],[Method Name]]=""), "", _xlfn.XLOOKUP(tblResults[[#This Row],[Product Name]]&tblResults[[#This Row],[Method Name]], Specifications!B:B&Specifications!D:D, Specifications!E:E, "No Spec"))} -> 0 | L4: {=IF(OR(tblResults[[#This Row],[Product Name]]="", tblResults[[#This Row],[Method Name]]=""), "", _xlfn.XLOOKUP(tblResults[[#This Row],[Product Name]]&tblResults[[#This Row],[Method Name]], Specifications!B:B&Specifications!D:D, Specifications!F:F, "No Spec"))} -> 100 | M4: =IF(tblResults[[#This Row],[Measured Value]]="","",IF(NOT(ISNUMBER(tblResults[[#This Row],[Measured Value]])),"Invalid Entry",IF(OR(tblResults[[#This Row],[Lower Limit]]="",tblResults[[#This Row],[Upper Limit]]="",tblResults[[#This Row],[Lower Limit]]="No Spec"),"",IF(AND(tblResults[[#This Row],[Measured Value]]>=tblResults[[#This Row],[Lower Limit]],tblResults[[#This Row],[Measured Value]]<=tblResults[[#This Row],[Upper Limit]]),"Pass","OOS")))) -> Pass
A5: R-2026-0004 | B5: SMP-2026-0004 | C5: =IF(tblResults[[#This Row],[Sample ID]]="", "", _xlfn.XLOOKUP(tblResults[[#This Row],[Sample ID]], Samples!A:A, Samples!C:C, "")) -> Paracetamol | D5: TM-002 | E5: =IF(tblResults[[#This Row],[Method ID]]="", "", _xlfn.XLOOKUP(tblResults[[#This Row],[Method ID]], 'Test Methods'!A:A, 'Test Methods'!B:B, "")) -> HPLC Assay | F5: 46149 | G5: 0.34998843 | H5: AOB | I5: 96.8 | J5: {=IF(OR(tblResults[[#This Row],[Product Name]]="", tblResults[[#This Row],[Method Name]]=""), "", _xlfn.XLOOKUP(tblResults[[#This Row],[Product Name]]&tblResults[[#This Row],[Method Name]], Specifications!B:B&Specifications!D:D, Specifications!G:G, "No Spec"))} -> % w/w | K5: {=IF(OR(tblResults[[#This Row],[Product Name]]="", tblResults[[#This Row],[Method Name]]=""), "", _xlfn.XLOOKUP(tblResults[[#This Row],[Product Name]]&tblResults[[#This Row],[Method Name]], Specifications!B:B&Specifications!D:D, Specifications!E:E, "No Spec"))} -> 95 | L5: {=IF(OR(tblResults[[#This Row],[Product Name]]="", tblResults[[#This Row],[Method Name]]=""), "", _xlfn.XLOOKUP(tblResults[[#This Row],[Product Name]]&tblResults[[#This Row],[Method Name]], Specifications!B:B&Specifications!D:D, Specifications!F:F, "No Spec"))} -> 105 | M5: =IF(tblResults[[#This Row],[Measured Value]]="","",IF(NOT(ISNUMBER(tblResults[[#This Row],[Measured Value]])),"Invalid Entry",IF(OR(tblResults[[#This Row],[Lower Limit]]="",tblResults[[#This Row],[Upper Limit]]="",tblResults[[#This Row],[Lower Limit]]="No Spec"),"",IF(AND(tblResults[[#This Row],[Measured Value]]>=tblResults[[#This Row],[Lower Limit]],tblResults[[#This Row],[Measured Value]]<=tblResults[[#This Row],[Upper Limit]]),"Pass","OOS")))) -> Pass
A6: R-2026-0005 | B6: SMP-2026-0003 | C6: =IF(tblResults[[#This Row],[Sample ID]]="", "", _xlfn.XLOOKUP(tblResults[[#This Row],[Sample ID]], Samples!A:A, Samples!C:C, "")) -> Paracetamol | D6: TM-001 | E6: =IF(tblResults[[#This Row],[Method ID]]="", "", _xlfn.XLOOKUP(tblResults[[#This Row],[Method ID]], 'Test Methods'!A:A, 'Test Methods'!B:B, "")) -> pH Test | F6: 46115 | G6: 0.39583333 | H6: AOB | I6: 6.1 | J6: {=IF(OR(tblResults[[#This Row],[Product Name]]="", tblResults[[#This Row],[Method Name]]=""), "", _xlfn.XLOOKUP(tblResults[[#This Row],[Product Name]]&tblResults[[#This Row],[Method Name]], Specifications!B:B&Specifications!D:D, Specifications!G:G, "No Spec"))} -> pH Units | K6: {=IF(OR(tblResults[[#This Row],[Product Name]]="", tblResults[[#This Row],[Method Name]]=""), "", _xlfn.XLOOKUP(tblResults[[#This Row],[Product Name]]&tblResults[[#This Row],[Method Name]], Specifications!B:B&Specifications!D:D, Specifications!E:E, "No Spec"))} -> 5.5 | L6: {=IF(OR(tblResults[[#This Row],[Product Name]]="", tblResults[[#This Row],[Method Name]]=""), "", _xlfn.XLOOKUP(tblResults[[#This Row],[Product Name]]&tblResults[[#This Row],[Method Name]], Specifications!B:B&Specifications!D:D, Specifications!F:F, "No Spec"))} -> 6.5 | M6: =IF(tblResults[[#This Row],[Measured Value]]="","",IF(NOT(ISNUMBER(tblResults[[#This Row],[Measured Value]])),"Invalid Entry",IF(OR(tblResults[[#This Row],[Lower Limit]]="",tblResults[[#This Row],[Upper Limit]]="",tblResults[[#This Row],[Lower Limit]]="No Spec"),"",IF(AND(tblResults[[#This Row],[Measured Value]]>=tblResults[[#This Row],[Lower Limit]],tblResults[[#This Row],[Measured Value]]<=tblResults[[#This Row],[Upper Limit]]),"Pass","OOS")))) -> Pass
A7: R-2026-0006 | B7: SMP-2026-0003 | C7: =IF(tblResults[[#This Row],[Sample ID]]="", "", _xlfn.XLOOKUP(tblResults[[#This Row],[Sample ID]], Samples!A:A, Samples!C:C, "")) -> Paracetamol | D7: TM-002 | E7: =IF(tblResults[[#This Row],[Method ID]]="", "", _xlfn.XLOOKUP(tblResults[[#This Row],[Method ID]], 'Test Methods'!A:A, 'Test Methods'!B:B, "")) -> HPLC Assay | F7: 46115 | G7: 0.46875 | H7: AOB | I7: 99.7 | J7: {=IF(OR(tblResults[[#This Row],[Product Name]]="", tblResults[[#This Row],[Method Name]]=""), "", _xlfn.XLOOKUP(tblResults[[#This Row],[Product Name]]&tblResults[[#This Row],[Method Name]], Specifications!B:B&Specifications!D:D, Specifications!G:G, "No Spec"))} -> % w/w | K7: {=IF(OR(tblResults[[#This Row],[Product Name]]="", tblResults[[#This Row],[Method Name]]=""), "", _xlfn.XLOOKUP(tblResults[[#This Row],[Product Name]]&tblResults[[#This Row],[Method Name]], Specifications!B:B&Specifications!D:D, Specifications!E:E, "No Spec"))} -> 95 | L7: {=IF(OR(tblResults[[#This Row],[Product Name]]="", tblResults[[#This Row],[Method Name]]=""), "", _xlfn.XLOOKUP(tblResults[[#This Row],[Product Name]]&tblResults[[#This Row],[Method Name]], Specifications!B:B&Specifications!D:D, Specifications!F:F, "No Spec"))} -> 105 | M7: =IF(tblResults[[#This Row],[Measured Value]]="","",IF(NOT(ISNUMBER(tblResults[[#This Row],[Measured Value]])),"Invalid Entry",IF(OR(tblResults[[#This Row],[Lower Limit]]="",tblResults[[#This Row],[Upper Limit]]="",tblResults[[#This Row],[Lower Limit]]="No Spec"),"",IF(AND(tblResults[[#This Row],[Measured Value]]>=tblResults[[#This Row],[Lower Limit]],tblResults[[#This Row],[Measured Value]]<=tblResults[[#This Row],[Upper Limit]]),"Pass","OOS")))) -> Pass
A8: R-2026-0007 | B8: SMP-2026-0003 | C8: =IF(tblResults[[#This Row],[Sample ID]]="", "", _xlfn.XLOOKUP(tblResults[[#This Row],[Sample ID]], Samples!A:A, Samples!C:C, "")) -> Paracetamol | D8: TM-004 | E8: =IF(tblResults[[#This Row],[Method ID]]="", "", _xlfn.XLOOKUP(tblResults[[#This Row],[Method ID]], 'Test Methods'!A:A, 'Test Methods'!B:B, "")) -> Dissolution | F8: 46115 | G8: 0.58333333 | H8: SK | I8: 92 | J8: {=IF(OR(tblResults[[#This Row],[Product Name]]="", tblResults[[#This Row],[Method Name]]=""), "", _xlfn.XLOOKUP(tblResults[[#This Row],[Product Name]]&tblResults[[#This Row],[Method Name]], Specifications!B:B&Specifications!D:D, Specifications!G:G, "No Spec"))} -> % released | K8: {=IF(OR(tblResults[[#This Row],[Product Name]]="", tblResults[[#This Row],[Method Name]]=""), "", _xlfn.XLOOKUP(tblResults[[#This Row],[Product Name]]&tblResults[[#This Row],[Method Name]], Specifications!B:B&Specifications!D:D, Specifications!E:E, "No Spec"))} -> 80 | L8: {=IF(OR(tblResults[[#This Row],[Product Name]]="", tblResults[[#This Row],[Method Name]]=""), "", _xlfn.XLOOKUP(tblResults[[#This Row],[Product Name]]&tblResults[[#This Row],[Method Name]], Specifications!B:B&Specifications!D:D, Specifications!F:F, "No Spec"))} -> 100 | M8: =IF(tblResults[[#This Row],[Measured Value]]="","",IF(NOT(ISNUMBER(tblResults[[#This Row],[Measured Value]])),"Invalid Entry",IF(OR(tblResults[[#This Row],[Lower Limit]]="",tblResults[[#This Row],[Upper Limit]]="",tblResults[[#This Row],[Lower Limit]]="No Spec"),"",IF(AND(tblResults[[#This Row],[Measured Value]]>=tblResults[[#This Row],[Lower Limit]],tblResults[[#This Row],[Measured Value]]<=tblResults[[#This Row],[Upper Limit]]),"Pass","OOS")))) -> Pass
A9: R-2026-0008 | B9: SMP-2026-0004 | C9: =IF(tblResults[[#This Row],[Sample ID]]="", "", _xlfn.XLOOKUP(tblResults[[#This Row],[Sample ID]], Samples!A:A, Samples!C:C, "")) -> Paracetamol | D9: TM-001 | E9: =IF(tblResults[[#This Row],[Method ID]]="", "", _xlfn.XLOOKUP(tblResults[[#This Row],[Method ID]], 'Test Methods'!A:A, 'Test Methods'!B:B, "")) -> pH Test | F9: 46121 | G9: 0.40625 | H9: JM | I9: 6 | J9: {=IF(OR(tblResults[[#This Row],[Product Name]]="", tblResults[[#This Row],[Method Name]]=""), "", _xlfn.XLOOKUP(tblResults[[#This Row],[Product Name]]&tblResults[[#This Row],[Method Name]], Specifications!B:B&Specifications!D:D, Specifications!G:G, "No Spec"))} -> pH Units | K9: {=IF(OR(tblResults[[#This Row],[Product Name]]="", tblResults[[#This Row],[Method Name]]=""), "", _xlfn.XLOOKUP(tblResults[[#This Row],[Product Name]]&tblResults[[#This Row],[Method Name]], Specifications!B:B&Specifications!D:D, Specifications!E:E, "No Spec"))} -> 5.5 | L9: {=IF(OR(tblResults[[#This Row],[Product Name]]="", tblResults[[#This Row],[Method Name]]=""), "", _xlfn.XLOOKUP(tblResults[[#This Row],[Product Name]]&tblResults[[#This Row],[Method Name]], Specifications!B:B&Specifications!D:D, Specifications!F:F, "No Spec"))} -> 6.5 | M9: =IF(tblResults[[#This Row],[Measured Value]]="","",IF(NOT(ISNUMBER(tblResults[[#This Row],[Measured Value]])),"Invalid Entry",IF(OR(tblResults[[#This Row],[Lower Limit]]="",tblResults[[#This Row],[Upper Limit]]="",tblResults[[#This Row],[Lower Limit]]="No Spec"),"",IF(AND(tblResults[[#This Row],[Measured Value]]>=tblResults[[#This Row],[Lower Limit]],tblResults[[#This Row],[Measured Value]]<=tblResults[[#This Row],[Upper Limit]]),"Pass","OOS")))) -> Pass
A10: R-2026-0009 | B10: SMP-2026-0004 | C10: =IF(tblResults[[#This Row],[Sample ID]]="", "", _xlfn.XLOOKUP(tblResults[[#This Row],[Sample ID]], Samples!A:A, Samples!C:C, "")) -> Paracetamol | D10: TM-002 | E10: =IF(tblResults[[#This Row],[Method ID]]="", "", _xlfn.XLOOKUP(tblResults[[#This Row],[Method ID]], 'Test Methods'!A:A, 'Test Methods'!B:B, "")) -> HPLC Assay | F10: 46121 | G10: 0.47916667 | H10: JM | I10: 101.2 | J10: {=IF(OR(tblResults[[#This Row],[Product Name]]="", tblResults[[#This Row],[Method Name]]=""), "", _xlfn.XLOOKUP(tblResults[[#This Row],[Product Name]]&tblResults[[#This Row],[Method Name]], Specifications!B:B&Specifications!D:D, Specifications!G:G, "No Spec"))} -> % w/w | K10: {=IF(OR(tblResults[[#This Row],[Product Name]]="", tblResults[[#This Row],[Method Name]]=""), "", _xlfn.XLOOKUP(tblResults[[#This Row],[Product Name]]&tblResults[[#This Row],[Method Name]], Specifications!B:B&Specifications!D:D, Specifications!E:E, "No Spec"))} -> 95 | L10: {=IF(OR(tblResults[[#This Row],[Product Name]]="", tblResults[[#This Row],[Method Name]]=""), "", _xlfn.XLOOKUP(tblResults[[#This Row],[Product Name]]&tblResults[[#This Row],[Method Name]], Specifications!B:B&Specifications!D:D, Specifications!F:F, "No Spec"))} -> 105 | M10: =IF(tblResults[[#This Row],[Measured Value]]="","",IF(NOT(ISNUMBER(tblResults[[#This Row],[Measured Value]])),"Invalid Entry",IF(OR(tblResults[[#This Row],[Lower Limit]]="",tblResults[[#This Row],[Upper Limit]]="",tblResults[[#This Row],[Lower Limit]]="No Spec"),"",IF(AND(tblResults[[#This Row],[Measured Value]]>=tblResults[[#This Row],[Lower Limit]],tblResults[[#This Row],[Measured Value]]<=tblResults[[#This Row],[Upper Limit]]),"Pass","OOS")))) -> Pass
A11: R-2026-0010 | B11: SMP-2026-0004 | C11: =IF(tblResults[[#This Row],[Sample ID]]="", "", _xlfn.XLOOKUP(tblResults[[#This Row],[Sample ID]], Samples!A:A, Samples!C:C, "")) -> Paracetamol | D11: TM-004 | E11: =IF(tblResults[[#This Row],[Method ID]]="", "", _xlfn.XLOOKUP(tblResults[[#This Row],[Method ID]], 'Test Methods'!A:A, 'Test Methods'!B:B, "")) -> Dissolution | F11: 46121 | G11: 0.57291667 | H11: AOB | I11: 88 | J11: {=IF(OR(tblResults[[#This Row],[Product Name]]="", tblResults[[#This Row],[Method Name]]=""), "", _xlfn.XLOOKUP(tblResults[[#This Row],[Product Name]]&tblResults[[#This Row],[Method Name]], Specifications!B:B&Specifications!D:D, Specifications!G:G, "No Spec"))} -> % released | K11: {=IF(OR(tblResults[[#This Row],[Product Name]]="", tblResults[[#This Row],[Method Name]]=""), "", _xlfn.XLOOKUP(tblResults[[#This Row],[Product Name]]&tblResults[[#This Row],[Method Name]], Specifications!B:B&Specifications!D:D, Specifications!E:E, "No Spec"))} -> 80 | L11: {=IF(OR(tblResults[[#This Row],[Product Name]]="", tblResults[[#This Row],[Method Name]]=""), "", _xlfn.XLOOKUP(tblResults[[#This Row],[Product Name]]&tblResults[[#This Row],[Method Name]], Specifications!B:B&Specifications!D:D, Specifications!F:F, "No Spec"))} -> 100 | M11: =IF(tblResults[[#This Row],[Measured Value]]="","",IF(NOT(ISNUMBER(tblResults[[#This Row],[Measured Value]])),"Invalid Entry",IF(OR(tblResults[[#This Row],[Lower Limit]]="",tblResults[[#This Row],[Upper Limit]]="",tblResults[[#This Row],[Lower Limit]]="No Spec"),"",IF(AND(tblResults[[#This Row],[Measured Value]]>=tblResults[[#This Row],[Lower Limit]],tblResults[[#This Row],[Measured Value]]<=tblResults[[#This Row],[Upper Limit]]),"Pass","OOS")))) -> Pass
A12: R-2026-0011 | B12: SMP-2026-0007 | C12: =IF(tblResults[[#This Row],[Sample ID]]="", "", _xlfn.XLOOKUP(tblResults[[#This Row],[Sample ID]], Samples!A:A, Samples!C:C, "")) -> Paracetamol | D12: TM-001 | E12: =IF(tblResults[[#This Row],[Method ID]]="", "", _xlfn.XLOOKUP(tblResults[[#This Row],[Method ID]], 'Test Methods'!A:A, 'Test Methods'!B:B, "")) -> pH Test | F12: 46133 | G12: 0.375 | H12: AOB | I12: 5.8 | J12: {=IF(OR(tblResults[[#This Row],[Product Name]]="", tblResults[[#This Row],[Method Name]]=""), "", _xlfn.XLOOKUP(tblResults[[#This Row],[Product Name]]&tblResults[[#This Row],[Method Name]], Specifications!B:B&Specifications!D:D, Specifications!G:G, "No Spec"))} -> pH Units | K12: {=IF(OR(tblResults[[#This Row],[Product Name]]="", tblResults[[#This Row],[Method Name]]=""), "", _xlfn.XLOOKUP(tblResults[[#This Row],[Product Name]]&tblResults[[#This Row],[Method Name]], Specifications!B:B&Specifications!D:D, Specifications!E:E, "No Spec"))} -> 5.5 | L12: {=IF(OR(tblResults[[#This Row],[Product Name]]="", tblResults[[#This Row],[Method Name]]=""), "", _xlfn.XLOOKUP(tblResults[[#This Row],[Product Name]]&tblResults[[#This Row],[Method Name]], Specifications!B:B&Specifications!D:D, Specifications!F:F, "No Spec"))} -> 6.5 | M12: =IF(tblResults[[#This Row],[Measured Value]]="","",IF(NOT(ISNUMBER(tblResults[[#This Row],[Measured Value]])),"Invalid Entry",IF(OR(tblResults[[#This Row],[Lower Limit]]="",tblResults[[#This Row],[Upper Limit]]="",tblResults[[#This Row],[Lower Limit]]="No Spec"),"",IF(AND(tblResults[[#This Row],[Measured Value]]>=tblResults[[#This Row],[Lower Limit]],tblResults[[#This Row],[Measured Value]]<=tblResults[[#This Row],[Upper Limit]]),"Pass","OOS")))) -> Pass
A13: R-2026-0012 | B13: SMP-2026-0007 | C13: =IF(tblResults[[#This Row],[Sample ID]]="", "", _xlfn.XLOOKUP(tblResults[[#This Row],[Sample ID]], Samples!A:A, Samples!C:C, "")) -> Paracetamol | D13: TM-002 | E13: =IF(tblResults[[#This Row],[Method ID]]="", "", _xlfn.XLOOKUP(tblResults[[#This Row],[Method ID]], 'Test Methods'!A:A, 'Test Methods'!B:B, "")) -> HPLC Assay | F13: 46133 | G13: 0.4375 | H13: SK | I13: 96.4 | J13: {=IF(OR(tblResults[[#This Row],[Product Name]]="", tblResults[[#This Row],[Method Name]]=""), "", _xlfn.XLOOKUP(tblResults[[#This Row],[Product Name]]&tblResults[[#This Row],[Method Name]], Specifications!B:B&Specifications!D:D, Specifications!G:G, "No Spec"))} -> % w/w | K13: {=IF(OR(tblResults[[#This Row],[Product Name]]="", tblResults[[#This Row],[Method Name]]=""), "", _xlfn.XLOOKUP(tblResults[[#This Row],[Product Name]]&tblResults[[#This Row],[Method Name]], Specifications!B:B&Specifications!D:D, Specifications!E:E, "No Spec"))} -> 95 | L13: {=IF(OR(tblResults[[#This Row],[Product Name]]="", tblResults[[#This Row],[Method Name]]=""), "", _xlfn.XLOOKUP(tblResults[[#This Row],[Product Name]]&tblResults[[#This Row],[Method Name]], Specifications!B:B&Specifications!D:D, Specifications!F:F, "No Spec"))} -> 105 | M13: =IF(tblResults[[#This Row],[Measured Value]]="","",IF(NOT(ISNUMBER(tblResults[[#This Row],[Measured Value]])),"Invalid Entry",IF(OR(tblResults[[#This Row],[Lower Limit]]="",tblResults[[#This Row],[Upper Limit]]="",tblResults[[#This Row],[Lower Limit]]="No Spec"),"",IF(AND(tblResults[[#This Row],[Measured Value]]>=tblResults[[#This Row],[Lower Limit]],tblResults[[#This Row],[Measured Value]]<=tblResults[[#This Row],[Upper Limit]]),"Pass","OOS")))) -> Pass
A14: R-2026-0013 | B14: SMP-2026-0008 | C14: =IF(tblResults[[#This Row],[Sample ID]]="", "", _xlfn.XLOOKUP(tblResults[[#This Row],[Sample ID]], Samples!A:A, Samples!C:C, "")) -> Paracetamol | D14: TM-002 | E14: =IF(tblResults[[#This Row],[Method ID]]="", "", _xlfn.XLOOKUP(tblResults[[#This Row],[Method ID]], 'Test Methods'!A:A, 'Test Methods'!B:B, "")) -> HPLC Assay | F14: 46135 | G14: 0.38541667 | H14: AOB | I14: 94.1 | J14: {=IF(OR(tblResults[[#This Row],[Product Name]]="", tblResults[[#This Row],[Method Name]]=""), "", _xlfn.XLOOKUP(tblResults[[#This Row],[Product Name]]&tblResults[[#This Row],[Method Name]], Specifications!B:B&Specifications!D:D, Specifications!G:G, "No Spec"))} -> % w/w | K14: {=IF(OR(tblResults[[#This Row],[Product Name]]="", tblResults[[#This Row],[Method Name]]=""), "", _xlfn.XLOOKUP(tblResults[[#This Row],[Product Name]]&tblResults[[#This Row],[Method Name]], Specifications!B:B&Specifications!D:D, Specifications!E:E, "No Spec"))} -> 95 | L14: {=IF(OR(tblResults[[#This Row],[Product Name]]="", tblResults[[#This Row],[Method Name]]=""), "", _xlfn.XLOOKUP(tblResults[[#This Row],[Product Name]]&tblResults[[#This Row],[Method Name]], Specifications!B:B&Specifications!D:D, Specifications!F:F, "No Spec"))} -> 105 | M14: =IF(tblResults[[#This Row],[Measured Value]]="","",IF(NOT(ISNUMBER(tblResults[[#This Row],[Measured Value]])),"Invalid Entry",IF(OR(tblResults[[#This Row],[Lower Limit]]="",tblResults[[#This Row],[Upper Limit]]="",tblResults[[#This Row],[Lower Limit]]="No Spec"),"",IF(AND(tblResults[[#This Row],[Measured Value]]>=tblResults[[#This Row],[Lower Limit]],tblResults[[#This Row],[Measured Value]]<=tblResults[[#This Row],[Upper Limit]]),"Pass","OOS")))) -> OOS | N14: Accelerated Stability
A15: R-2026-0014 | B15: SMP-2026-0009 | C15: =IF(tblResults[[#This Row],[Sample ID]]="", "", _xlfn.XLOOKUP(tblResults[[#This Row],[Sample ID]], Samples!A:A, Samples!C:C, "")) -> Ozempic | D15: TM-001 | E15: =IF(tblResults[[#This Row],[Method ID]]="", "", _xlfn.XLOOKUP(tblResults[[#This Row],[Method ID]], 'Test Methods'!A:A, 'Test Methods'!B:B, "")) -> pH Test | F15: 46118 | G15: 0.39583333 | H15: MM | I15: 7.2 | J15: {=IF(OR(tblResults[[#This Row],[Product Name]]="", tblResults[[#This Row],[Method Name]]=""), "", _xlfn.XLOOKUP(tblResults[[#This Row],[Product Name]]&tblResults[[#This Row],[Method Name]], Specifications!B:B&Specifications!D:D, Specifications!G:G, "No Spec"))} -> pH Units | K15: {=IF(OR(tblResults[[#This Row],[Product Name]]="", tblResults[[#This Row],[Method Name]]=""), "", _xlfn.XLOOKUP(tblResults[[#This Row],[Product Name]]&tblResults[[#This Row],[Method Name]], Specifications!B:B&Specifications!D:D, Specifications!E:E, "No Spec"))} -> 6.5 | L15: {=IF(OR(tblResults[[#This Row],[Product Name]]="", tblResults[[#This Row],[Method Name]]=""), "", _xlfn.XLOOKUP(tblResults[[#This Row],[Product Name]]&tblResults[[#This Row],[Method Name]], Specifications!B:B&Specifications!D:D, Specifications!F:F, "No Spec"))} -> 8 | M15: =IF(tblResults[[#This Row],[Measured Value]]="","",IF(NOT(ISNUMBER(tblResults[[#This Row],[Measured Value]])),"Invalid Entry",IF(OR(tblResults[[#This Row],[Lower Limit]]="",tblResults[[#This Row],[Upper Limit]]="",tblResults[[#This Row],[Lower Limit]]="No Spec"),"",IF(AND(tblResults[[#This Row],[Measured Value]]>=tblResults[[#This Row],[Lower Limit]],tblResults[[#This Row],[Measured Value]]<=tblResults[[#This Row],[Upper Limit]]),"Pass","OOS")))) -> Pass
A16: R-2026-0015 | B16: SMP-2026-0009 | C16: =IF(tblResults[[#This Row],[Sample ID]]="", "", _xlfn.XLOOKUP(tblResults[[#This Row],[Sample ID]], Samples!A:A, Samples!C:C, "")) -> Ozempic | D16: TM-002 | E16: =IF(tblResults[[#This Row],[Method ID]]="", "", _xlfn.XLOOKUP(tblResults[[#This Row],[Method ID]], 'Test Methods'!A:A, 'Test Methods'!B:B, "")) -> HPLC Assay | F16: 46118 | G16: 0.47916667 | H16: MM | I16: 100.4 | J16: {=IF(OR(tblResults[[#This Row],[Product Name]]="", tblResults[[#This Row],[Method Name]]=""), "", _xlfn.XLOOKUP(tblResults[[#This Row],[Product Name]]&tblResults[[#This Row],[Method Name]], Specifications!B:B&Specifications!D:D, Specifications!G:G, "No Spec"))} -> % w/w | K16: {=IF(OR(tblResults[[#This Row],[Product Name]]="", tblResults[[#This Row],[Method Name]]=""), "", _xlfn.XLOOKUP(tblResults[[#This Row],[Product Name]]&tblResults[[#This Row],[Method Name]], Specifications!B:B&Specifications!D:D, Specifications!E:E, "No Spec"))} -> 98 | L16: {=IF(OR(tblResults[[#This Row],[Product Name]]="", tblResults[[#This Row],[Method Name]]=""), "", _xlfn.XLOOKUP(tblResults[[#This Row],[Product Name]]&tblResults[[#This Row],[Method Name]], Specifications!B:B&Specifications!D:D, Specifications!F:F, "No Spec"))} -> 102 | M16: =IF(tblResults[[#This Row],[Measured Value]]="","",IF(NOT(ISNUMBER(tblResults[[#This Row],[Measured Value]])),"Invalid Entry",IF(OR(tblResults[[#This Row],[Lower Limit]]="",tblResults[[#This Row],[Upper Limit]]="",tblResults[[#This Row],[Lower Limit]]="No Spec"),"",IF(AND(tblResults[[#This Row],[Measured Value]]>=tblResults[[#This Row],[Lower Limit]],tblResults[[#This Row],[Measured Value]]<=tblResults[[#This Row],[Upper Limit]]),"Pass","OOS")))) -> Pass
A17: R-2026-0016 | B17: SMP-2026-0009 | C17: =IF(tblResults[[#This Row],[Sample ID]]="", "", _xlfn.XLOOKUP(tblResults[[#This Row],[Sample ID]], Samples!A:A, Samples!C:C, "")) -> Ozempic | D17: TM-006 | E17: =IF(tblResults[[#This Row],[Method ID]]="", "", _xlfn.XLOOKUP(tblResults[[#This Row],[Method ID]], 'Test Methods'!A:A, 'Test Methods'!B:B, "")) -> Microbial Count | F17: 46118 | G17: 0.58333333 | H17: SK | I17: 12 | J17: {=IF(OR(tblResults[[#This Row],[Product Name]]="", tblResults[[#This Row],[Method Name]]=""), "", _xlfn.XLOOKUP(tblResults[[#This Row],[Product Name]]&tblResults[[#This Row],[Method Name]], Specifications!B:B&Specifications!D:D, Specifications!G:G, "No Spec"))} -> CFU/g | K17: {=IF(OR(tblResults[[#This Row],[Product Name]]="", tblResults[[#This Row],[Method Name]]=""), "", _xlfn.XLOOKUP(tblResults[[#This Row],[Product Name]]&tblResults[[#This Row],[Method Name]], Specifications!B:B&Specifications!D:D, Specifications!E:E, "No Spec"))} -> 0 | L17: {=IF(OR(tblResults[[#This Row],[Product Name]]="", tblResults[[#This Row],[Method Name]]=""), "", _xlfn.XLOOKUP(tblResults[[#This Row],[Product Name]]&tblResults[[#This Row],[Method Name]], Specifications!B:B&Specifications!D:D, Specifications!F:F, "No Spec"))} -> 100 | M17: =IF(tblResults[[#This Row],[Measured Value]]="","",IF(NOT(ISNUMBER(tblResults[[#This Row],[Measured Value]])),"Invalid Entry",IF(OR(tblResults[[#This Row],[Lower Limit]]="",tblResults[[#This Row],[Upper Limit]]="",tblResults[[#This Row],[Lower Limit]]="No Spec"),"",IF(AND(tblResults[[#This Row],[Measured Value]]>=tblResults[[#This Row],[Lower Limit]],tblResults[[#This Row],[Measured Value]]<=tblResults[[#This Row],[Upper Limit]]),"Pass","OOS")))) -> Pass
A18: R-2026-0017 | B18: SMP-2026-0010 | C18: =IF(tblResults[[#This Row],[Sample ID]]="", "", _xlfn.XLOOKUP(tblResults[[#This Row],[Sample ID]], Samples!A:A, Samples!C:C, "")) -> Ozempic | D18: TM-001 | E18: =IF(tblResults[[#This Row],[Method ID]]="", "", _xlfn.XLOOKUP(tblResults[[#This Row],[Method ID]], 'Test Methods'!A:A, 'Test Methods'!B:B, "")) -> pH Test | F18: 46124 | G18: 0.40625 | H18: AOB | I18: 7.4 | J18: {=IF(OR(tblResults[[#This Row],[Product Name]]="", tblResults[[#This Row],[Method Name]]=""), "", _xlfn.XLOOKUP(tblResults[[#This Row],[Product Name]]&tblResults[[#This Row],[Method Name]], Specifications!B:B&Specifications!D:D, Specifications!G:G, "No Spec"))} -> pH Units | K18: {=IF(OR(tblResults[[#This Row],[Product Name]]="", tblResults[[#This Row],[Method Name]]=""), "", _xlfn.XLOOKUP(tblResults[[#This Row],[Product Name]]&tblResults[[#This Row],[Method Name]], Specifications!B:B&Specifications!D:D, Specifications!E:E, "No Spec"))} -> 6.5 | L18: {=IF(OR(tblResults[[#This Row],[Product Name]]="", tblResults[[#This Row],[Method Name]]=""), "", _xlfn.XLOOKUP(tblResults[[#This Row],[Product Name]]&tblResults[[#This Row],[Method Name]], Specifications!B:B&Specifications!D:D, Specifications!F:F, "No Spec"))} -> 8 | M18: =IF(tblResults[[#This Row],[Measured Value]]="","",IF(NOT(ISNUMBER(tblResults[[#This Row],[Measured Value]])),"Invalid Entry",IF(OR(tblResults[[#This Row],[Lower Limit]]="",tblResults[[#This Row],[Upper Limit]]="",tblResults[[#This Row],[Lower Limit]]="No Spec"),"",IF(AND(tblResults[[#This Row],[Measured Value]]>=tblResults[[#This Row],[Lower Limit]],tblResults[[#This Row],[Measured Value]]<=tblResults[[#This Row],[Upper Limit]]),"Pass","OOS")))) -> Pass
A19: R-2026-0018 | B19: SMP-2026-0010 | C19: =IF(tblResults[[#This Row],[Sample ID]]="", "", _xlfn.XLOOKUP(tblResults[[#This Row],[Sample ID]], Samples!A:A, Samples!C:C, "")) -> Ozempic | D19: TM-002 | E19: =IF(tblResults[[#This Row],[Method ID]]="", "", _xlfn.XLOOKUP(tblResults[[#This Row],[Method ID]], 'Test Methods'!A:A, 'Test Methods'!B:B, "")) -> HPLC Assay | F19: 46124 | G19: 0.47916667 | H19: AOB | I19: 99.8 | J19: {=IF(OR(tblResults[[#This Row],[Product Name]]="", tblResults[[#This Row],[Method Name]]=""), "", _xlfn.XLOOKUP(tblResults[[#This Row],[Product Name]]&tblResults[[#This Row],[Method Name]], Specifications!B:B&Specifications!D:D, Specifications!G:G, "No Spec"))} -> % w/w | K19: {=IF(OR(tblResults[[#This Row],[Product Name]]="", tblResults[[#This Row],[Method Name]]=""), "", _xlfn.XLOOKUP(tblResults[[#This Row],[Product Name]]&tblResults[[#This Row],[Method Name]], Specifications!B:B&Specifications!D:D, Specifications!E:E, "No Spec"))} -> 98 | L19: {=IF(OR(tblResults[[#This Row],[Product Name]]="", tblResults[[#This Row],[Method Name]]=""), "", _xlfn.XLOOKUP(tblResults[[#This Row],[Product Name]]&tblResults[[#This Row],[Method Name]], Specifications!B:B&Specifications!D:D, Specifications!F:F, "No Spec"))} -> 102 | M19: =IF(tblResults[[#This Row],[Measured Value]]="","",IF(NOT(ISNUMBER(tblResults[[#This Row],[Measured Value]])),"Invalid Entry",IF(OR(tblResults[[#This Row],[Lower Limit]]="",tblResults[[#This Row],[Upper Limit]]="",tblResults[[#This Row],[Lower Limit]]="No Spec"),"",IF(AND(tblResults[[#This Row],[Measured Value]]>=tblResults[[#This Row],[Lower Limit]],tblResults[[#This Row],[Measured Value]]<=tblResults[[#This Row],[Upper Limit]]),"Pass","OOS")))) -> Pass
A20: R-2026-0019 | B20: SMP-2026-0011 | C20: =IF(tblResults[[#This Row],[Sample ID]]="", "", _xlfn.XLOOKUP(tblResults[[#This Row],[Sample ID]], Samples!A:A, Samples!C:C, "")) -> Ozempic | D20: TM-001 | E20: =IF(tblResults[[#This Row],[Method ID]]="", "", _xlfn.XLOOKUP(tblResults[[#This Row],[Method ID]], 'Test Methods'!A:A, 'Test Methods'!B:B, "")) -> pH Test | F20: 46129 | G20: 0.39583333 | H20: JM | I20: 7 | J20: {=IF(OR(tblResults[[#This Row],[Product Name]]="", tblResults[[#This Row],[Method Name]]=""), "", _xlfn.XLOOKUP(tblResults[[#This Row],[Product Name]]&tblResults[[#This Row],[Method Name]], Specifications!B:B&Specifications!D:D, Specifications!G:G, "No Spec"))} -> pH Units | K20: {=IF(OR(tblResults[[#This Row],[Product Name]]="", tblResults[[#This Row],[Method Name]]=""), "", _xlfn.XLOOKUP(tblResults[[#This Row],[Product Name]]&tblResults[[#This Row],[Method Name]], Specifications!B:B&Specifications!D:D, Specifications!E:E, "No Spec"))} -> 6.5 | L20: {=IF(OR(tblResults[[#This Row],[Product Name]]="", tblResults[[#This Row],[Method Name]]=""), "", _xlfn.XLOOKUP(tblResults[[#This Row],[Product Name]]&tblResults[[#This Row],[Method Name]], Specifications!B:B&Specifications!D:D, Specifications!F:F, "No Spec"))} -> 8 | M20: =IF(tblResults[[#This Row],[Measured Value]]="","",IF(NOT(ISNUMBER(tblResults[[#This Row],[Measured Value]])),"Invalid Entry",IF(OR(tblResults[[#This Row],[Lower Limit]]="",tblResults[[#This Row],[Upper Limit]]="",tblResults[[#This Row],[Lower Limit]]="No Spec"),"",IF(AND(tblResults[[#This Row],[Measured Value]]>=tblResults[[#This Row],[Lower Limit]],tblResults[[#This Row],[Measured Value]]<=tblResults[[#This Row],[Upper Limit]]),"Pass","OOS")))) -> Pass
A21: R-2026-0020 | B21: SMP-2026-0011 | C21: =IF(tblResults[[#This Row],[Sample ID]]="", "", _xlfn.XLOOKUP(tblResults[[#This Row],[Sample ID]], Samples!A:A, Samples!C:C, "")) -> Ozempic | D21: TM-002 | E21: =IF(tblResults[[#This Row],[Method ID]]="", "", _xlfn.XLOOKUP(tblResults[[#This Row],[Method ID]], 'Test Methods'!A:A, 'Test Methods'!B:B, "")) -> HPLC Assay | F21: 46129 | G21: 0.46875 | H21: JM | I21: 96.2 | J21: {=IF(OR(tblResults[[#This Row],[Product Name]]="", tblResults[[#This Row],[Method Name]]=""), "", _xlfn.XLOOKUP(tblResults[[#This Row],[Product Name]]&tblResults[[#This Row],[Method Name]], Specifications!B:B&Specifications!D:D, Specifications!G:G, "No Spec"))} -> % w/w | K21: {=IF(OR(tblResults[[#This Row],[Product Name]]="", tblResults[[#This Row],[Method Name]]=""), "", _xlfn.XLOOKUP(tblResults[[#This Row],[Product Name]]&tblResults[[#This Row],[Method Name]], Specifications!B:B&Specifications!D:D, Specifications!E:E, "No Spec"))} -> 98 | L21: {=IF(OR(tblResults[[#This Row],[Product Name]]="", tblResults[[#This Row],[Method Name]]=""), "", _xlfn.XLOOKUP(tblResults[[#This Row],[Product Name]]&tblResults[[#This Row],[Method Name]], Specifications!B:B&Specifications!D:D, Specifications!F:F, "No Spec"))} -> 102 | M21: =IF(tblResults[[#This Row],[Measured Value]]="","",IF(NOT(ISNUMBER(tblResults[[#This Row],[Measured Value]])),"Invalid Entry",IF(OR(tblResults[[#This Row],[Lower Limit]]="",tblResults[[#This Row],[Upper Limit]]="",tblResults[[#This Row],[Lower Limit]]="No Spec"),"",IF(AND(tblResults[[#This Row],[Measured Value]]>=tblResults[[#This Row],[Lower Limit]],tblResults[[#This Row],[Measured Value]]<=tblResults[[#This Row],[Upper Limit]]),"Pass","OOS")))) -> OOS | N21: Pre-Rejection
A22: R-2026-0021 | B22: SMP-2026-0014 | C22: =IF(tblResults[[#This Row],[Sample ID]]="", "", _xlfn.XLOOKUP(tblResults[[#This Row],[Sample ID]], Samples!A:A, Samples!C:C, "")) -> Ozempic | D22: TM-001 | E22: =IF(tblResults[[#This Row],[Method ID]]="", "", _xlfn.XLOOKUP(tblResults[[#This Row],[Method ID]], 'Test Methods'!A:A, 'Test Methods'!B:B, "")) -> pH Test | F22: 46136 | G22: 0.54166667 | H22: SK | I22: 7.3 | J22: {=IF(OR(tblResults[[#This Row],[Product Name]]="", tblResults[[#This Row],[Method Name]]=""), "", _xlfn.XLOOKUP(tblResults[[#This Row],[Product Name]]&tblResults[[#This Row],[Method Name]], Specifications!B:B&Specifications!D:D, Specifications!G:G, "No Spec"))} -> pH Units | K22: {=IF(OR(tblResults[[#This Row],[Product Name]]="", tblResults[[#This Row],[Method Name]]=""), "", _xlfn.XLOOKUP(tblResults[[#This Row],[Product Name]]&tblResults[[#This Row],[Method Name]], Specifications!B:B&Specifications!D:D, Specifications!E:E, "No Spec"))} -> 6.5 | L22: {=IF(OR(tblResults[[#This Row],[Product Name]]="", tblResults[[#This Row],[Method Name]]=""), "", _xlfn.XLOOKUP(tblResults[[#This Row],[Product Name]]&tblResults[[#This Row],[Method Name]], Specifications!B:B&Specifications!D:D, Specifications!F:F, "No Spec"))} -> 8 | M22: =IF(tblResults[[#This Row],[Measured Value]]="","",IF(NOT(ISNUMBER(tblResults[[#This Row],[Measured Value]])),"Invalid Entry",IF(OR(tblResults[[#This Row],[Lower Limit]]="",tblResults[[#This Row],[Upper Limit]]="",tblResults[[#This Row],[Lower Limit]]="No Spec"),"",IF(AND(tblResults[[#This Row],[Measured Value]]>=tblResults[[#This Row],[Lower Limit]],tblResults[[#This Row],[Measured Value]]<=tblResults[[#This Row],[Upper Limit]]),"Pass","OOS")))) -> Pass
A23: R-2026-0022 | B23: SMP-2026-0014 | C23: =IF(tblResults[[#This Row],[Sample ID]]="", "", _xlfn.XLOOKUP(tblResults[[#This Row],[Sample ID]], Samples!A:A, Samples!C:C, "")) -> Ozempic | D23: TM-002 | E23: =IF(tblResults[[#This Row],[Method ID]]="", "", _xlfn.XLOOKUP(tblResults[[#This Row],[Method ID]], 'Test Methods'!A:A, 'Test Methods'!B:B, "")) -> HPLC Assay | F23: 46136 | G23: 0.60416667 | H23: SK | I23: 99.1 | J23: {=IF(OR(tblResults[[#This Row],[Product Name]]="", tblResults[[#This Row],[Method Name]]=""), "", _xlfn.XLOOKUP(tblResults[[#This Row],[Product Name]]&tblResults[[#This Row],[Method Name]], Specifications!B:B&Specifications!D:D, Specifications!G:G, "No Spec"))} -> % w/w | K23: {=IF(OR(tblResults[[#This Row],[Product Name]]="", tblResults[[#This Row],[Method Name]]=""), "", _xlfn.XLOOKUP(tblResults[[#This Row],[Product Name]]&tblResults[[#This Row],[Method Name]], Specifications!B:B&Specifications!D:D, Specifications!E:E, "No Spec"))} -> 98 | L23: {=IF(OR(tblResults[[#This Row],[Product Name]]="", tblResults[[#This Row],[Method Name]]=""), "", _xlfn.XLOOKUP(tblResults[[#This Row],[Product Name]]&tblResults[[#This Row],[Method Name]], Specifications!B:B&Specifications!D:D, Specifications!F:F, "No Spec"))} -> 102 | M23: =IF(tblResults[[#This Row],[Measured Value]]="","",IF(NOT(ISNUMBER(tblResults[[#This Row],[Measured Value]])),"Invalid Entry",IF(OR(tblResults[[#This Row],[Lower Limit]]="",tblResults[[#This Row],[Upper Limit]]="",tblResults[[#This Row],[Lower Limit]]="No Spec"),"",IF(AND(tblResults[[#This Row],[Measured Value]]>=tblResults[[#This Row],[Lower Limit]],tblResults[[#This Row],[Measured Value]]<=tblResults[[#This Row],[Upper Limit]]),"Pass","OOS")))) -> Pass
A24: R-2026-0023 | B24: SMP-2026-0015 | C24: =IF(tblResults[[#This Row],[Sample ID]]="", "", _xlfn.XLOOKUP(tblResults[[#This Row],[Sample ID]], Samples!A:A, Samples!C:C, "")) -> Ibuprofen | D24: TM-002 | E24: =IF(tblResults[[#This Row],[Method ID]]="", "", _xlfn.XLOOKUP(tblResults[[#This Row],[Method ID]], 'Test Methods'!A:A, 'Test Methods'!B:B, "")) -> HPLC Assay | F24: 46122 | G24: 0.39583333 | H24: JM | I24: 102.5 | J24: {=IF(OR(tblResults[[#This Row],[Product Name]]="", tblResults[[#This Row],[Method Name]]=""), "", _xlfn.XLOOKUP(tblResults[[#This Row],[Product Name]]&tblResults[[#This Row],[Method Name]], Specifications!B:B&Specifications!D:D, Specifications!G:G, "No Spec"))} -> % w/w | K24: {=IF(OR(tblResults[[#This Row],[Product Name]]="", tblResults[[#This Row],[Method Name]]=""), "", _xlfn.XLOOKUP(tblResults[[#This Row],[Product Name]]&tblResults[[#This Row],[Method Name]], Specifications!B:B&Specifications!D:D, Specifications!E:E, "No Spec"))} -> 90 | L24: {=IF(OR(tblResults[[#This Row],[Product Name]]="", tblResults[[#This Row],[Method Name]]=""), "", _xlfn.XLOOKUP(tblResults[[#This Row],[Product Name]]&tblResults[[#This Row],[Method Name]], Specifications!B:B&Specifications!D:D, Specifications!F:F, "No Spec"))} -> 110 | M24: =IF(tblResults[[#This Row],[Measured Value]]="","",IF(NOT(ISNUMBER(tblResults[[#This Row],[Measured Value]])),"Invalid Entry",IF(OR(tblResults[[#This Row],[Lower Limit]]="",tblResults[[#This Row],[Upper Limit]]="",tblResults[[#This Row],[Lower Limit]]="No Spec"),"",IF(AND(tblResults[[#This Row],[Measured Value]]>=tblResults[[#This Row],[Lower Limit]],tblResults[[#This Row],[Measured Value]]<=tblResults[[#This Row],[Upper Limit]]),"Pass","OOS")))) -> Pass
A25: R-2026-0024 | B25: SMP-2026-0015 | C25: =IF(tblResults[[#This Row],[Sample ID]]="", "", _xlfn.XLOOKUP(tblResults[[#This Row],[Sample ID]], Samples!A:A, Samples!C:C, "")) -> Ibuprofen | D25: TM-004 | E25: =IF(tblResults[[#This Row],[Method ID]]="", "", _xlfn.XLOOKUP(tblResults[[#This Row],[Method ID]], 'Test Methods'!A:A, 'Test Methods'!B:B, "")) -> Dissolution | F25: 46122 | G25: 0.46875 | H25: JM | I25: 95 | J25: {=IF(OR(tblResults[[#This Row],[Product Name]]="", tblResults[[#This Row],[Method Name]]=""), "", _xlfn.XLOOKUP(tblResults[[#This Row],[Product Name]]&tblResults[[#This Row],[Method Name]], Specifications!B:B&Specifications!D:D, Specifications!G:G, "No Spec"))} -> % released | K25: {=IF(OR(tblResults[[#This Row],[Product Name]]="", tblResults[[#This Row],[Method Name]]=""), "", _xlfn.XLOOKUP(tblResults[[#This Row],[Product Name]]&tblResults[[#This Row],[Method Name]], Specifications!B:B&Specifications!D:D, Specifications!E:E, "No Spec"))} -> 80 | L25: {=IF(OR(tblResults[[#This Row],[Product Name]]="", tblResults[[#This Row],[Method Name]]=""), "", _xlfn.XLOOKUP(tblResults[[#This Row],[Product Name]]&tblResults[[#This Row],[Method Name]], Specifications!B:B&Specifications!D:D, Specifications!F:F, "No Spec"))} -> 100 | M25: =IF(tblResults[[#This Row],[Measured Value]]="","",IF(NOT(ISNUMBER(tblResults[[#This Row],[Measured Value]])),"Invalid Entry",IF(OR(tblResults[[#This Row],[Lower Limit]]="",tblResults[[#This Row],[Upper Limit]]="",tblResults[[#This Row],[Lower Limit]]="No Spec"),"",IF(AND(tblResults[[#This Row],[Measured Value]]>=tblResults[[#This Row],[Lower Limit]],tblResults[[#This Row],[Measured Value]]<=tblResults[[#This Row],[Upper Limit]]),"Pass","OOS")))) -> Pass
A26: R-2026-0025 | B26: SMP-2026-0015 | C26: =IF(tblResults[[#This Row],[Sample ID]]="", "", _xlfn.XLOOKUP(tblResults[[#This Row],[Sample ID]], Samples!A:A, Samples!C:C, "")) -> Ibuprofen | D26: TM-005 | E26: =IF(tblResults[[#This Row],[Method ID]]="", "", _xlfn.XLOOKUP(tblResults[[#This Row],[Method ID]], 'Test Methods'!A:A, 'Test Methods'!B:B, "")) -> Water Content (KF) | F26: 46122 | G26: 0.5625 | H26: AOB | I26: 3.2 | J26: {=IF(OR(tblResults[[#This Row],[Product Name]]="", tblResults[[#This Row],[Method Name]]=""), "", _xlfn.XLOOKUP(tblResults[[#This Row],[Product Name]]&tblResults[[#This Row],[Method Name]], Specifications!B:B&Specifications!D:D, Specifications!G:G, "No Spec"))} -> % w/w | K26: {=IF(OR(tblResults[[#This Row],[Product Name]]="", tblResults[[#This Row],[Method Name]]=""), "", _xlfn.XLOOKUP(tblResults[[#This Row],[Product Name]]&tblResults[[#This Row],[Method Name]], Specifications!B:B&Specifications!D:D, Specifications!E:E, "No Spec"))} -> 0 | L26: {=IF(OR(tblResults[[#This Row],[Product Name]]="", tblResults[[#This Row],[Method Name]]=""), "", _xlfn.XLOOKUP(tblResults[[#This Row],[Product Name]]&tblResults[[#This Row],[Method Name]], Specifications!B:B&Specifications!D:D, Specifications!F:F, "No Spec"))} -> 5 | M26: =IF(tblResults[[#This Row],[Measured Value]]="","",IF(NOT(ISNUMBER(tblResults[[#This Row],[Measured Value]])),"Invalid Entry",IF(OR(tblResults[[#This Row],[Lower Limit]]="",tblResults[[#This Row],[Upper Limit]]="",tblResults[[#This Row],[Lower Limit]]="No Spec"),"",IF(AND(tblResults[[#This Row],[Measured Value]]>=tblResults[[#This Row],[Lower Limit]],tblResults[[#This Row],[Measured Value]]<=tblResults[[#This Row],[Upper Limit]]),"Pass","OOS")))) -> Pass
A27: R-2026-0026 | B27: SMP-2026-0016 | C27: =IF(tblResults[[#This Row],[Sample ID]]="", "", _xlfn.XLOOKUP(tblResults[[#This Row],[Sample ID]], Samples!A:A, Samples!C:C, "")) -> Ibuprofen | D27: TM-002 | E27: =IF(tblResults[[#This Row],[Method ID]]="", "", _xlfn.XLOOKUP(tblResults[[#This Row],[Method ID]], 'Test Methods'!A:A, 'Test Methods'!B:B, "")) -> HPLC Assay | F27: 46130 | G27: 0.38541667 | H27: MM | I27: 89.5 | J27: {=IF(OR(tblResults[[#This Row],[Product Name]]="", tblResults[[#This Row],[Method Name]]=""), "", _xlfn.XLOOKUP(tblResults[[#This Row],[Product Name]]&tblResults[[#This Row],[Method Name]], Specifications!B:B&Specifications!D:D, Specifications!G:G, "No Spec"))} -> % w/w | K27: {=IF(OR(tblResults[[#This Row],[Product Name]]="", tblResults[[#This Row],[Method Name]]=""), "", _xlfn.XLOOKUP(tblResults[[#This Row],[Product Name]]&tblResults[[#This Row],[Method Name]], Specifications!B:B&Specifications!D:D, Specifications!E:E, "No Spec"))} -> 90 | L27: {=IF(OR(tblResults[[#This Row],[Product Name]]="", tblResults[[#This Row],[Method Name]]=""), "", _xlfn.XLOOKUP(tblResults[[#This Row],[Product Name]]&tblResults[[#This Row],[Method Name]], Specifications!B:B&Specifications!D:D, Specifications!F:F, "No Spec"))} -> 110 | M27: =IF(tblResults[[#This Row],[Measured Value]]="","",IF(NOT(ISNUMBER(tblResults[[#This Row],[Measured Value]])),"Invalid Entry",IF(OR(tblResults[[#This Row],[Lower Limit]]="",tblResults[[#This Row],[Upper Limit]]="",tblResults[[#This Row],[Lower Limit]]="No Spec"),"",IF(AND(tblResults[[#This Row],[Measured Value]]>=tblResults[[#This Row],[Lower Limit]],tblResults[[#This Row],[Measured Value]]<=tblResults[[#This Row],[Upper Limit]]),"Pass","OOS")))) -> OOS | N27: OOS Investigation Pending
A28: R-2026-0027 | B28: SMP-2026-0016 | C28: =IF(tblResults[[#This Row],[Sample ID]]="", "", _xlfn.XLOOKUP(tblResults[[#This Row],[Sample ID]], Samples!A:A, Samples!C:C, "")) -> Ibuprofen | D28: TM-004 | E28: =IF(tblResults[[#This Row],[Method ID]]="", "", _xlfn.XLOOKUP(tblResults[[#This Row],[Method ID]], 'Test Methods'!A:A, 'Test Methods'!B:B, "")) -> Dissolution | F28: 46130 | G28: 0.47916667 | H28: MM | I28: 78 | J28: {=IF(OR(tblResults[[#This Row],[Product Name]]="", tblResults[[#This Row],[Method Name]]=""), "", _xlfn.XLOOKUP(tblResults[[#This Row],[Product Name]]&tblResults[[#This Row],[Method Name]], Specifications!B:B&Specifications!D:D, Specifications!G:G, "No Spec"))} -> % released | K28: {=IF(OR(tblResults[[#This Row],[Product Name]]="", tblResults[[#This Row],[Method Name]]=""), "", _xlfn.XLOOKUP(tblResults[[#This Row],[Product Name]]&tblResults[[#This Row],[Method Name]], Specifications!B:B&Specifications!D:D, Specifications!E:E, "No Spec"))} -> 80 | L28: {=IF(OR(tblResults[[#This Row],[Product Name]]="", tblResults[[#This Row],[Method Name]]=""), "", _xlfn.XLOOKUP(tblResults[[#This Row],[Product Name]]&tblResults[[#This Row],[Method Name]], Specifications!B:B&Specifications!D:D, Specifications!F:F, "No Spec"))} -> 100 | M28: =IF(tblResults[[#This Row],[Measured Value]]="","",IF(NOT(ISNUMBER(tblResults[[#This Row],[Measured Value]])),"Invalid Entry",IF(OR(tblResults[[#This Row],[Lower Limit]]="",tblResults[[#This Row],[Upper Limit]]="",tblResults[[#This Row],[Lower Limit]]="No Spec"),"",IF(AND(tblResults[[#This Row],[Measured Value]]>=tblResults[[#This Row],[Lower Limit]],tblResults[[#This Row],[Measured Value]]<=tblResults[[#This Row],[Upper Limit]]),"Pass","OOS")))) -> OOS | N28: OOS Investigation Pending
A29: R-2026-0028 | B29: SMP-2026-0018 | C29: =IF(tblResults[[#This Row],[Sample ID]]="", "", _xlfn.XLOOKUP(tblResults[[#This Row],[Sample ID]], Samples!A:A, Samples!C:C, "")) -> Ibuprofen | D29: TM-002 | E29: =IF(tblResults[[#This Row],[Method ID]]="", "", _xlfn.XLOOKUP(tblResults[[#This Row],[Method ID]], 'Test Methods'!A:A, 'Test Methods'!B:B, "")) -> HPLC Assay | F29: 46139 | G29: 0.5625 | H29: AOB | I29: 100.8 | J29: {=IF(OR(tblResults[[#This Row],[Product Name]]="", tblResults[[#This Row],[Method Name]]=""), "", _xlfn.XLOOKUP(tblResults[[#This Row],[Product Name]]&tblResults[[#This Row],[Method Name]], Specifications!B:B&Specifications!D:D, Specifications!G:G, "No Spec"))} -> % w/w | K29: {=IF(OR(tblResults[[#This Row],[Product Name]]="", tblResults[[#This Row],[Method Name]]=""), "", _xlfn.XLOOKUP(tblResults[[#This Row],[Product Name]]&tblResults[[#This Row],[Method Name]], Specifications!B:B&Specifications!D:D, Specifications!E:E, "No Spec"))} -> 90 | L29: {=IF(OR(tblResults[[#This Row],[Product Name]]="", tblResults[[#This Row],[Method Name]]=""), "", _xlfn.XLOOKUP(tblResults[[#This Row],[Product Name]]&tblResults[[#This Row],[Method Name]], Specifications!B:B&Specifications!D:D, Specifications!F:F, "No Spec"))} -> 110 | M29: =IF(tblResults[[#This Row],[Measured Value]]="","",IF(NOT(ISNUMBER(tblResults[[#This Row],[Measured Value]])),"Invalid Entry",IF(OR(tblResults[[#This Row],[Lower Limit]]="",tblResults[[#This Row],[Upper Limit]]="",tblResults[[#This Row],[Lower Limit]]="No Spec"),"",IF(AND(tblResults[[#This Row],[Measured Value]]>=tblResults[[#This Row],[Lower Limit]],tblResults[[#This Row],[Measured Value]]<=tblResults[[#This Row],[Upper Limit]]),"Pass","OOS")))) -> Pass
A30: R-2026-0029 | B30: SMP-2026-0007 | C30: =IF(tblResults[[#This Row],[Sample ID]]="", "", _xlfn.XLOOKUP(tblResults[[#This Row],[Sample ID]], Samples!A:A, Samples!C:C, "")) -> Paracetamol | D30: TM-004 | E30: =IF(tblResults[[#This Row],[Method ID]]="", "", _xlfn.XLOOKUP(tblResults[[#This Row],[Method ID]], 'Test Methods'!A:A, 'Test Methods'!B:B, "")) -> Dissolution | F30: 46151 | G30: 0.66666667 | H30: MM | I30: 76.2 | J30: {=IF(OR(tblResults[[#This Row],[Product Name]]="", tblResults[[#This Row],[Method Name]]=""), "", _xlfn.XLOOKUP(tblResults[[#This Row],[Product Name]]&tblResults[[#This Row],[Method Name]], Specifications!B:B&Specifications!D:D, Specifications!G:G, "No Spec"))} -> % released | K30: {=IF(OR(tblResults[[#This Row],[Product Name]]="", tblResults[[#This Row],[Method Name]]=""), "", _xlfn.XLOOKUP(tblResults[[#This Row],[Product Name]]&tblResults[[#This Row],[Method Name]], Specifications!B:B&Specifications!D:D, Specifications!E:E, "No Spec"))} -> 80 | L30: {=IF(OR(tblResults[[#This Row],[Product Name]]="", tblResults[[#This Row],[Method Name]]=""), "", _xlfn.XLOOKUP(tblResults[[#This Row],[Product Name]]&tblResults[[#This Row],[Method Name]], Specifications!B:B&Specifications!D:D, Specifications!F:F, "No Spec"))} -> 100 | M30: =IF(tblResults[[#This Row],[Measured Value]]="","",IF(NOT(ISNUMBER(tblResults[[#This Row],[Measured Value]])),"Invalid Entry",IF(OR(tblResults[[#This Row],[Lower Limit]]="",tblResults[[#This Row],[Upper Limit]]="",tblResults[[#This Row],[Lower Limit]]="No Spec"),"",IF(AND(tblResults[[#This Row],[Measured Value]]>=tblResults[[#This Row],[Lower Limit]],tblResults[[#This Row],[Measured Value]]<=tblResults[[#This Row],[Upper Limit]]),"Pass","OOS")))) -> OOS
E31: =IF(tblResults[[#This Row],[Method ID]]="", "", _xlfn.XLOOKUP(tblResults[[#This Row],[Method ID]], 'Test Methods'!A:A, 'Test Methods'!B:B, "")) | J31: {=IF(OR(tblResults[[#This Row],[Product Name]]="", tblResults[[#This Row],[Method Name]]=""), "", _xlfn.XLOOKUP(tblResults[[#This Row],[Product Name]]&tblResults[[#This Row],[Method Name]], Specifications!B:B&Specifications!D:D, Specifications!G:G, "No Spec"))} | K31: {=IF(OR(tblResults[[#This Row],[Product Name]]="", tblResults[[#This Row],[Method Name]]=""), "", _xlfn.XLOOKUP(tblResults[[#This Row],[Product Name]]&tblResults[[#This Row],[Method Name]], Specifications!B:B&Specifications!D:D, Specifications!E:E, "No Spec"))} | L31: {=IF(OR(tblResults[[#This Row],[Product Name]]="", tblResults[[#This Row],[Method Name]]=""), "", _xlfn.XLOOKUP(tblResults[[#This Row],[Product Name]]&tblResults[[#This Row],[Method Name]], Specifications!B:B&Specifications!D:D, Specifications!F:F, "No Spec"))} | M31: =IF(tblResults[[#This Row],[Measured Value]]="","",IF(NOT(ISNUMBER(tblResults[[#This Row],[Measured Value]])),"Invalid Entry",IF(OR(tblResults[[#This Row],[Lower Limit]]="",tblResults[[#This Row],[Upper Limit]]="",tblResults[[#This Row],[Lower Limit]]="No Spec"),"",IF(AND(tblResults[[#This Row],[Measured Value]]>=tblResults[[#This Row],[Lower Limit]],tblResults[[#This Row],[Measured Value]]<=tblResults[[#This Row],[Upper Limit]]),"Pass","OOS"))))

Sheet Chain of Custody
A1: CoC ID | B1: Sample ID | C1: Date | D1: Time | E1: Action | F1: From Location | G1: To Location | H1: Handled By | I1: Comments
A2: CoC-2026-0001 | B2: SMP-2026-0005 | C2: 46131 | D2: 0.36497685 | E2: Received | F2: External | G2: Reception | H2: JM
A3: CoC-2026-0002 | B3: SMP-2026-0005 | C3: 46131 | D3: 0.37513889 | E3: Transferred | F3: Reception | G3: QC Bench 1 | H3: JM
A4: CoC-2026-0003 | B4: SMP-2026-0005 | C4: 46131 | D4: 0.42775463 | E4: Tested | F4: QC Bench 1 | G4: QC Bench 1 | H4: AOB
A5: CoC-2026-0004 | B5: SMP-2026-0005 | C5: 46131 | D5: 0.61005787 | E5: Stored | F5: QC Bench 1 | G5: Lab Storage | H5: AOB
